Workbook

Sheet Dashboard
A1: CUSTOMER CHURN — EXECUTIVE DASHBOARD
A2: Decision view | 5,000 customers | Formula-driven KPIs | Predictive risk + revenue exposure
A4: View Filter | B4: All
A6: Customers | E6: Churned | I6: Churn Rate
A7: =IF($B$4="All",COUNTA(Analysis_Data!$A$5:$A$5004),COUNTIF(Analysis_Data!$D$5:$D$5004,$B$4)) -> 5000 | E7: =IF($B$4="All",COUNTIF(Analysis_Data!$J$5:$J$5004,1),COUNTIFS(Analysis_Data!$D$5:$D$5004,$B$4,Analysis_Data!$J$5:$J$5004,1)) -> 2515 | I7: =IFERROR(E7/A7,0) -> 0.503
A10: Avg Monthly Fee | E10: Revenue at Risk | I10: Critical Risk
A11: =IF($B$4="All",AVERAGE(Analysis_Data!$I$5:$I$5004),AVERAGEIF(Analysis_Data!$D$5:$D$5004,$B$4,Analysis_Data!$I$5:$I$5004)) -> 13.6834 | E11: =IF($B$4="All",SUM(Analysis_Data!$W$5:$W$5004),SUMIF(Analysis_Data!$D$5:$D$5004,$B$4,Analysis_Data!$W$5:$W$5004)) -> 45579.058 | I11: =IF($B$4="All",COUNTIF(Analysis_Data!$V$5:$V$5004,"Critical"),COUNTIFS(Analysis_Data!$D$5:$D$5004,$B$4,Analysis_Data!$V$5:$V$5004,"Critical")) -> 3022
A15: MANAGEMENT VIEW
A16: Basic churn rate | E16: High + Critical risk | I16: Top subscription revenue risk
A17: =IFERROR(COUNTIFS(Analysis_Data!$D$5:$D$5004,"Basic",Analysis_Data!$J$5:$J$5004,1)/COUNTIF(Analysis_Data!$D$5:$D$5004,"Basic"),0) -> 0.61830223 | E17: =COUNTIF(Analysis_Data!$V$5:$V$5004,"High")+COUNTIF(Analysis_Data!$V$5:$V$5004,"Critical") -> 3391 | I17: =INDEX(Churn_Analysis!$A$6:$A$8,MATCH(MAX(Churn_Analysis!$G$6:$G$8),Churn_Analysis!$G$6:$G$8,0)) -> Premium
A21: CHURN BY SUBSCRIPTION | H21: RISK DISTRIBUTION
A22: Subscription | B22: Customers | C22: Churned | D22: Churn Rate | H22: Risk Band | I22: Customers | J22: % Customers
A23: Basic | B23: =COUNTIF(Analysis_Data!$D$5:$D$5004,A23) -> 1661 | C23: =COUNTIFS(Analysis_Data!$D$5:$D$5004,A23,Analysis_Data!$J$5:$J$5004,1) -> 1027 | D23: =IFERROR(C23/B23,0) -> 0.61830223 | H23: Low | I23: =COUNTIF(Analysis_Data!$V$5:$V$5004,H23) -> 1305 | J23: =IFERROR(I23/$B$6,0) -> 0
A24: Standard | B24: =COUNTIF(Analysis_Data!$D$5:$D$5004,A24) -> 1646 | C24: =COUNTIFS(Analysis_Data!$D$5:$D$5004,A24,Analysis_Data!$J$5:$J$5004,1) -> 748 | D24: =IFERROR(C24/B24,0) -> 0.45443499 | H24: Medium | I24: =COUNTIF(Analysis_Data!$V$5:$V$5004,H24) -> 304 | J24: =IFERROR(I24/$B$6,0) -> 0
A25: Premium | B25: =COUNTIF(Analysis_Data!$D$5:$D$5004,A25) -> 1693 | C25: =COUNTIFS(Analysis_Data!$D$5:$D$5004,A25,Analysis_Data!$J$5:$J$5004,1) -> 740 | D25: =IFERROR(C25/B25,0) -> 0.43709392 | H25: High | I25: =COUNTIF(Analysis_Data!$V$5:$V$5004,H25) -> 369 | J25: =IFERROR(I25/$B$6,0) -> 0
H26: Critical | I26: =COUNTIF(Analysis_Data!$V$5:$V$5004,H26) -> 3022 | J26: =IFERROR(I26/$B$6,0) -> 0
A43: Analyst note: use this dashboard as a decision-support layer. Validate high-risk actions with business context and future data before operational deployment.
A46: Tip: change the View Filter in B4 to Basic / Standard / Premium. KPI cards update automatically; the lower charts remain portfolio-level for segment comparison.

Sheet README
A1: STREAMING CUSTOMER CHURN — ANALYTICS PORTFOLIO
A2: Excel-first Data Analyst / Data Science portfolio workbook | Source: uploaded customer churn CSV | 5,000 records
A4: PROJECT OVERVIEW
A5: Project Objective | B5: Analyze customer churn, identify behavioral/financial drivers, quantify revenue at risk, and create an Excel-based retention decision framework.
A6: Business Question | B6: Which customer segments show elevated churn risk, what behaviors correlate with churn, and where should retention teams focus first?
A7: Dataset | B7: 5,000 customers × 14 source fields. No missing values detected in the supplied file.
A8: Core Analyst Work | B8: Data quality checks, calculated fields, segmentation, KPI design, cohort-style comparisons, summary tables, conditional formatting, charts, and dashboard reporting.
A9: Data Science Layer | B9: A logistic-regression churn model is included. Coefficients are embedded into Excel and the customer-level probability is calculated with an Excel logistic formula.
A10: Important Note | B10: The uploaded file is treated as a portfolio dataset. It is not presented as official Netflix corporate data.
A11: How to Use | B11: Open Dashboard first → use the filter selector → review Churn Analysis / Customer Segments → inspect Predictive Model → use Raw_Data for row-level evidence.
A12: Interview Story | B12: Frame the project around: problem definition → data cleaning → KPI design → exploratory analysis → segmentation → predictive scoring → business recommendations → limitations.
A15: WORKBOOK MAP
A16: Dashboard | B16: Executive KPI dashboard and management view.
A17: Raw_Data | B17: Original source data preserved as an Excel Table.
A18: Analysis_Data | B18: Formula-driven row-level metrics, segmentation and churn probability.
A19: Churn_Analysis | B19: Dimension-level churn rates, counts, averages and revenue-at-risk views.
A20: Customer_Segments | B20: Behavioral segments built from engagement + recency + risk.
A21: Predictive_Model | B21: Logistic-regression coefficients, model evaluation and Excel scoring logic.
A22: Data_Quality | B22: Completeness, duplicates, range checks and category checks.
A23: Data_Dictionary | B23: Field definitions and analytical role.
A24: Analyst_Notes | B24: Interview-ready observations, assumptions and limitations.

Sheet Raw_Data
A1: RAW DATA
A2: Source data preserved from the uploaded CSV. No source rows removed.
A4: customer_id | B4: age | C4: gender | D4: subscription_type | E4: watch_hours | F4: last_login_days | G4: region | H4: device | I4: monthly_fee | J4: churned | K4: payment_method | L4: number_of_profiles | M4: avg_watch_time_per_day | N4: favorite_genre
A5: a9b75100-82a8-427a-a208-72f24052884a | B5: 51 | C5: Other | D5: Basic | E5: 14.73 | F5: 29 | G5: Africa | H5: TV | I5: 8.99 | J5: 1 | K5: Gift Card | L5: 1 | M5: 0.49 | N5: Action
A6: 49a5dfd9-7e69-4022-a6ad-0a1b9767fb5b | B6: 47 | C6: Other | D6: Standard | E6: 0.7 | F6: 19 | G6: Europe | H6: Mobile | I6: 13.99 | J6: 1 | K6: Gift Card | L6: 5 | M6: 0.03 | N6: Sci-Fi
A7: 4d71f6ce-fca9-4ff7-8afa-197ac24de14b | B7: 27 | C7: Female | D7: Standard | E7: 16.32 | F7: 10 | G7: Asia | H7: TV | I7: 13.99 | J7: 0 | K7: Crypto | L7: 2 | M7: 1.48 | N7: Drama
A8: d3c72c38-631b-4f9e-8a0e-de103cad1a7d | B8: 53 | C8: Other | D8: Premium | E8: 4.51 | F8: 12 | G8: Oceania | H8: TV | I8: 17.99 | J8: 1 | K8: Crypto | L8: 2 | M8: 0.35 | N8: Horror
A9: 4e265c34-103a-4dbb-9553-76c9aa47e946 | B9: 56 | C9: Other | D9: Standard | E9: 1.89 | F9: 13 | G9: Africa | H9: Mobile | I9: 13.99 | J9: 1 | K9: Crypto | L9: 2 | M9: 0.13 | N9: Action
A10: d8079475-5be7-47e9-8782-ceb7ff61395e | B10: 58 | C10: Female | D10: Standard | E10: 13.8 | F10: 26 | G10: Oceania | H10: Mobile | I10: 13.99 | J10: 0 | K10: Debit Card | L10: 3 | M10: 0.51 | N10: Action
A11: 8e63450a-13d6-4e83-bbb5-6aebde9152cb | B11: 48 | C11: Other | D11: Basic | E11: 13.83 | F11: 20 | G11: Asia | H11: TV | I11: 8.99 | J11: 0 | K11: Gift Card | L11: 5 | M11: 0.66 | N11: Romance
A12: 02387681-8c42-462a-807a-de0168c73b38 | B12: 51 | C12: Male | D12: Basic | E12: 14.3 | F12: 56 | G12: Europe | H12: Mobile | I12: 8.99 | J12: 1 | K12: Gift Card | L12: 1 | M12: 0.25 | N12: Action
A13: 0bcaad0c-545c-4ee1-85a6-75e165f39361 | B13: 45 | C13: Other | D13: Basic | E13: 9.98 | F13: 10 | G13: Asia | H13: Mobile | I13: 8.99 | J13: 0 | K13: PayPal | L13: 3 | M13: 0.91 | N13: Romance
A14: eae6439e-8cdf-4258-ab49-c493925b927a | B14: 32 | C14: Other | D14: Premium | E14: 2.22 | F14: 34 | G14: Europe | H14: TV | I14: 17.99 | J14: 1 | K14: Debit Card | L14: 1 | M14: 0.06 | N14: Drama
A15: 45a03ce3-26d0-4cd5-a9bd-22d42490b612 | B15: 26 | C15: Male | D15: Premium | E15: 15.42 | F15: 36 | G15: Asia | H15: Laptop | I15: 17.99 | J15: 0 | K15: Debit Card | L15: 4 | M15: 0.42 | N15: Comedy
A16: 9df43ad1-d6ee-44d0-a79b-c8ab444f10bf | B16: 28 | C16: Other | D16: Standard | E16: 22.26 | F16: 38 | G16: South America | H16: Mobile | I16: 13.99 | J16: 0 | K16: Crypto | L16: 5 | M16: 0.57 | N16: Horror
... A5004: 82aeef39-ddb0-40ad-bae1-5c436e0cf042 | B5004: 57 | C5004: Male | D5004: Basic | E5004: 1.62 | F5004: 17 | G5004: Africa | H5004: Mobile | I5004: 8.99 | J5004: 1 | K5004: Crypto | L5004: 2 | M5004: 0.09 | N5004: Action

Sheet Analysis_Data
A1: ANALYSIS DATA
A2: Formula-driven analytical layer. All added fields recalculate from Raw_Data.
A4: customer_id | B4: age | C4: gender | D4: subscription_type | E4: watch_hours | F4: last_login_days | G4: region | H4: device | I4: monthly_fee | J4: churned | K4: payment_method | L4: number_of_profiles | M4: avg_watch_time_per_day | N4: favorite_genre | O4: age_band | P4: watch_band | Q4: recency_band | R4: engagement_band | S4: fee_band | T4: churn_label | U4: churn_risk_probability | V4: risk_band | W4: revenue_at_risk | X4: priority_flag | Y4: data_quality_flag
A5: =Raw_Data!A5 -> a9b75100-82a8-427a-a208-72f24052884a | B5: =Raw_Data!B5 -> 51 | C5: =Raw_Data!C5 -> Other | D5: =Raw_Data!D5 -> Basic | E5: =Raw_Data!E5 -> 14.73 | F5: =Raw_Data!F5 -> 29 | G5: =Raw_Data!G5 -> Africa | H5: =Raw_Data!H5 -> TV | ... N5: =Raw_Data!N5 -> Action | O5: =IF(B5<25,"18-24",IF(B5<35,"25-34",IF(B5<45,"35-44",IF(B5<55,"45-54","55-70")))) -> 45-54 | P5: =IF(E5<10,"<10h",IF(E5<25,"10-24h",IF(E5<50,"25-49h","50h+"))) -> 10-24h | Q5: =IF(F5<=7,"0-7d",IF(F5<=21,"8-21d",IF(F5<=45,"22-45d","46-60d"))) -> 22-45d | R5: =IF(AND(E5>=25,F5<=21),"High",IF(OR(E5>=10,F5<=45),"Medium","Low")) -> Medium | S5: =IF(I5<10,"Low",IF(I5<16,"Mid","High")) -> Low | T5: =IF(J5=1,"Churned","Active") -> Churned | U5: =1/(1+EXP(-(Predictive_Model!$B$5+((B5-Predictive_Model!$B$20)/Predictive_Model!$C$20)*Predictive_Model!$D$20+((E5-Predictive_Model!$B$21)/Predictive_Model!$C$21)*Predictive_Model!$D$21+((F5-Predictive_Model!$B$22)/Predictive_Model!$C$22)*Predictive_Model!$D$22+((I5-Predictive_Model!$B$23)/Predictive_Model!$C$23)*Predictive_Model!$D$23+((L5-Predictive_Model!$B$24)/Predictive_Model!$C$24)*Predictive_Model!$D$24+((M5-Predictive_Model!$B$25)/Predictive_Model!$C$25)*Predictive_Model!$D$25+IF(C5="Male",Predictive_Model!$D$31,IF(C5="Other",Predictive_Model!$D$32,0))+IF(D5="Premium",Predictive_Model!$D$34,IF(D5="Standard",Predictive_Model!$D$35,0))+IF(G5="Asia",Predictive_Model!$D$37,IF(G5="Europe",Predictive_Model!$D$38,IF(G5="North America",Predictive_Model!$D$39,IF(G5="Oceania",Predictive_Model!$D$40,IF(G5="South America",Predictive_Model!$D$41,0)))))+IF(H5="Laptop",Predictive_Model!$D$43,IF(H5="Mobile",Predictive_Model!$D$44,IF(H5="TV",Predictive_Model!$D$45,IF(H5="Tablet",Predictive_Model!$D$46,0))))+IF(K5="Crypto",Predictive_Model!$D$48,IF(K5="Debit Card",Predictive_Model!$D$49,IF(K5="Gift Card",Predictive_Model!$D$50,IF(K5="PayPal",Predictive_Model!$D$51,0))))+IF(N5="Comedy",Predictive_Model!$D$53,IF(N5="Documentary",Predictive_Model!$D$54,IF(N5="Drama",Predictive_Model!$D$55,IF(N5="Horror",Predictive_Model!$D$56,IF(N5="Romance",Predictive_Model!$D$57,IF(N5="Sci-Fi",Predictive_Model!$D$58,0))))))))) -> 0.9532337 | V5: =IF(U5>=0.75,"Critical",IF(U5>=0.5,"High",IF(U5>=0.25,"Medium","Low"))) -> Critical | W5: =IF(J5=1,I5,I5*U5) -> 8.99 | X5: =IF(AND(V5="Critical",I5>=15),"Priority 1",IF(OR(V5="Critical",AND(V5="High",F5>21)),"Priority 2","Monitor")) -> Priority 2 | Y5: =IF(COUNTA(A5:N5)=14,"OK","CHECK") -> OK
A6: =Raw_Data!A6 -> 49a5dfd9-7e69-4022-a6ad-0a1b9767fb5b | B6: =Raw_Data!B6 -> 47 | C6: =Raw_Data!C6 -> Other | D6: =Raw_Data!D6 -> Standard | E6: =Raw_Data!E6 -> 0.7 | F6: =Raw_Data!F6 -> 19 | G6: =Raw_Data!G6 -> Europe | H6: =Raw_Data!H6 -> Mobile | ... N6: =Raw_Data!N6 -> Sci-Fi | O6: =IF(B6<25,"18-24",IF(B6<35,"25-34",IF(B6<45,"35-44",IF(B6<55,"45-54","55-70")))) -> 45-54 | P6: =IF(E6<10,"<10h",IF(E6<25,"10-24h",IF(E6<50,"25-49h","50h+"))) -> <10h | Q6: =IF(F6<=7,"0-7d",IF(F6<=21,"8-21d",IF(F6<=45,"22-45d","46-60d"))) -> 8-21d | R6: =IF(AND(E6>=25,F6<=21),"High",IF(OR(E6>=10,F6<=45),"Medium","Low")) -> Medium | S6: =IF(I6<10,"Low",IF(I6<16,"Mid","High")) -> Mid | T6: =IF(J6=1,"Churned","Active") -> Churned | U6: =1/(1+EXP(-(Predictive_Model!$B$5+((B6-Predictive_Model!$B$20)/Predictive_Model!$C$20)*Predictive_Model!$D$20+((E6-Predictive_Model!$B$21)/Predictive_Model!$C$21)*Predictive_Model!$D$21+((F6-Predictive_Model!$B$22)/Predictive_Model!$C$22)*Predictive_Model!$D$22+((I6-Predictive_Model!$B$23)/Predictive_Model!$C$23)*Predictive_Model!$D$23+((L6-Predictive_Model!$B$24)/Predictive_Model!$C$24)*Predictive_Model!$D$24+((M6-Predictive_Model!$B$25)/Predictive_Model!$C$25)*Predictive_Model!$D$25+IF(C6="Male",Predictive_Model!$D$31,IF(C6="Other",Predictive_Model!$D$32,0))+IF(D6="Premium",Predictive_Model!$D$34,IF(D6="Standard",Predictive_Model!$D$35,0))+IF(G6="Asia",Predictive_Model!$D$37,IF(G6="Europe",Predictive_Model!$D$38,IF(G6="North America",Predictive_Model!$D$39,IF(G6="Oceania",Predictive_Model!$D$40,IF(G6="South America",Predictive_Model!$D$41,0)))))+IF(H6="Laptop",Predictive_Model!$D$43,IF(H6="Mobile",Predictive_Model!$D$44,IF(H6="TV",Predictive_Model!$D$45,IF(H6="Tablet",Predictive_Model!$D$46,0))))+IF(K6="Crypto",Predictive_Model!$D$48,IF(K6="Debit Card",Predictive_Model!$D$49,IF(K6="Gift Card",Predictive_Model!$D$50,IF(K6="PayPal",Predictive_Model!$D$51,0))))+IF(N6="Comedy",Predictive_Model!$D$53,IF(N6="Documentary",Predictive_Model!$D$54,IF(N6="Drama",Predictive_Model!$D$55,IF(N6="Horror",Predictive_Model!$D$56,IF(N6="Romance",Predictive_Model!$D$57,IF(N6="Sci-Fi",Predictive_Model!$D$58,0))))))))) -> 0.989129 | V6: =IF(U6>=0.75,"Critical",IF(U6>=0.5,"High",IF(U6>=0.25,"Medium","Low"))) -> Critical | W6: =IF(J6=1,I6,I6*U6) -> 13.99 | X6: =IF(AND(V6="Critical",I6>=15),"Priority 1",IF(OR(V6="Critical",AND(V6="High",F6>21)),"Priority 2","Monitor")) -> Priority 2 | Y6: =IF(COUNTA(A6:N6)=14,"OK","CHECK") -> OK
A7: =Raw_Data!A7 -> 4d71f6ce-fca9-4ff7-8afa-197ac24de14b | B7: =Raw_Data!B7 -> 27 | C7: =Raw_Data!C7 -> Female | D7: =Raw_Data!D7 -> Standard | E7: =Raw_Data!E7 -> 16.32 | F7: =Raw_Data!F7 -> 10 | G7: =Raw_Data!G7 -> Asia | H7: =Raw_Data!H7 -> TV | ... N7: =Raw_Data!N7 -> Drama | O7: =IF(B7<25,"18-24",IF(B7<35,"25-34",IF(B7<45,"35-44",IF(B7<55,"45-54","55-70")))) -> 25-34 | P7: =IF(E7<10,"<10h",IF(E7<25,"10-24h",IF(E7<50,"25-49h","50h+"))) -> 10-24h | Q7: =IF(F7<=7,"0-7d",IF(F7<=21,"8-21d",IF(F7<=45,"22-45d","46-60d"))) -> 8-21d | R7: =IF(AND(E7>=25,F7<=21),"High",IF(OR(E7>=10,F7<=45),"Medium","Low")) -> Medium | S7: =IF(I7<10,"Low",IF(I7<16,"Mid","High")) -> Mid | T7: =IF(J7=1,"Churned","Active") -> Active | U7: =1/(1+EXP(-(Predictive_Model!$B$5+((B7-Predictive_Model!$B$20)/Predictive_Model!$C$20)*Predictive_Model!$D$20+((E7-Predictive_Model!$B$21)/Predictive_Model!$C$21)*Predictive_Model!$D$21+((F7-Predictive_Model!$B$22)/Predictive_Model!$C$22)*Predictive_Model!$D$22+((I7-Predictive_Model!$B$23)/Predictive_Model!$C$23)*Predictive_Model!$D$23+((L7-Predictive_Model!$B$24)/Predictive_Model!$C$24)*Predictive_Model!$D$24+((M7-Predictive_Model!$B$25)/Predictive_Model!$C$25)*Predictive_Model!$D$25+IF(C7="Male",Predictive_Model!$D$31,IF(C7="Other",Predictive_Model!$D$32,0))+IF(D7="Premium",Predictive_Model!$D$34,IF(D7="Standard",Predictive_Model!$D$35,0))+IF(G7="Asia",Predictive_Model!$D$37,IF(G7="Europe",Predictive_Model!$D$38,IF(G7="North America",Predictive_Model!$D$39,IF(G7="Oceania",Predictive_Model!$D$40,IF(G7="South America",Predictive_Model!$D$41,0)))))+IF(H7="Laptop",Predictive_Model!$D$43,IF(H7="Mobile",Predictive_Model!$D$44,IF(H7="TV",Predictive_Model!$D$45,IF(H7="Tablet",Predictive_Model!$D$46,0))))+IF(K7="Crypto",Predictive_Model!$D$48,IF(K7="Debit Card",Predictive_Model!$D$49,IF(K7="Gift Card",Predictive_Model!$D$50,IF(K7="PayPal",Predictive_Model!$D$51,0))))+IF(N7="Comedy",Predictive_Model!$D$53,IF(N7="Documentary",Predictive_Model!$D$54,IF(N7="Drama",Predictive_Model!$D$55,IF(N7="Horror",Predictive_Model!$D$56,IF(N7="Romance",Predictive_Model!$D$57,IF(N7="Sci-Fi",Predictive_Model!$D$58,0))))))))) -> 0.018015191 | V7: =IF(U7>=0.75,"Critical",IF(U7>=0.5,"High",IF(U7>=0.25,"Medium","Low"))) -> Low | W7: =IF(J7=1,I7,I7*U7) -> 0.25203253 | X7: =IF(AND(V7="Critical",I7>=15),"Priority 1",IF(OR(V7="Critical",AND(V7="High",F7>21)),"Priority 2","Monitor")) -> Monitor | Y7: =IF(COUNTA(A7:N7)=14,"OK","CHECK") -> OK
A8: =Raw_Data!A8 -> d3c72c38-631b-4f9e-8a0e-de103cad1a7d | B8: =Raw_Data!B8 -> 53 | C8: =Raw_Data!C8 -> Other | D8: =Raw_Data!D8 -> Premium | E8: =Raw_Data!E8 -> 4.51 | F8: =Raw_Data!F8 -> 12 | G8: =Raw_Data!G8 -> Oceania | H8: =Raw_Data!H8 -> TV | ... N8: =Raw_Data!N8 -> Horror | O8: =IF(B8<25,"18-24",IF(B8<35,"25-34",IF(B8<45,"35-44",IF(B8<55,"45-54","55-70")))) -> 45-54 | P8: =IF(E8<10,"<10h",IF(E8<25,"10-24h",IF(E8<50,"25-49h","50h+"))) -> <10h | Q8: =IF(F8<=7,"0-7d",IF(F8<=21,"8-21d",IF(F8<=45,"22-45d","46-60d"))) -> 8-21d | R8: =IF(AND(E8>=25,F8<=21),"High",IF(OR(E8>=10,F8<=45),"Medium","Low")) -> Medium | S8: =IF(I8<10,"Low",IF(I8<16,"Mid","High")) -> High | T8: =IF(J8=1,"Churned","Active") -> Churned | U8: =1/(1+EXP(-(Predictive_Model!$B$5+((B8-Predictive_Model!$B$20)/Predictive_Model!$C$20)*Predictive_Model!$D$20+((E8-Predictive_Model!$B$21)/Predictive_Model!$C$21)*Predictive_Model!$D$21+((F8-Predictive_Model!$B$22)/Predictive_Model!$C$22)*Predictive_Model!$D$22+((I8-Predictive_Model!$B$23)/Predictive_Model!$C$23)*Predictive_Model!$D$23+((L8-Predictive_Model!$B$24)/Predictive_Model!$C$24)*Predictive_Model!$D$24+((M8-Predictive_Model!$B$25)/Predictive_Model!$C$25)*Predictive_Model!$D$25+IF(C8="Male",Predictive_Model!$D$31,IF(C8="Other",Predictive_Model!$D$32,0))+IF(D8="Premium",Predictive_Model!$D$34,IF(D8="Standard",Predictive_Model!$D$35,0))+IF(G8="Asia",Predictive_Model!$D$37,IF(G8="Europe",Predictive_Model!$D$38,IF(G8="North America",Predictive_Model!$D$39,IF(G8="Oceania",Predictive_Model!$D$40,IF(G8="South America",Predictive_Model!$D$41,0)))))+IF(H8="Laptop",Predictive_Model!$D$43,IF(H8="Mobile",Predictive_Model!$D$44,IF(H8="TV",Predictive_Model!$D$45,IF(H8="Tablet",Predictive_Model!$D$46,0))))+IF(K8="Crypto",Predictive_Model!$D$48,IF(K8="Debit Card",Predictive_Model!$D$49,IF(K8="Gift Card",Predictive_Model!$D$50,IF(K8="PayPal",Predictive_Model!$D$51,0))))+IF(N8="Comedy",Predictive_Model!$D$53,IF(N8="Documentary",Predictive_Model!$D$54,IF(N8="Drama",Predictive_Model!$D$55,IF(N8="Horror",Predictive_Model!$D$56,IF(N8="Romance",Predictive_Model!$D$57,IF(N8="Sci-Fi",Predictive_Model!$D$58,0))))))))) -> 0.56831628 | V8: =IF(U8>=0.75,"Critical",IF(U8>=0.5,"High",IF(U8>=0.25,"Medium","Low"))) -> High | W8: =IF(J8=1,I8,I8*U8) -> 17.99 | X8: =IF(AND(V8="Critical",I8>=15),"Priority 1",IF(OR(V8="Critical",AND(V8="High",F8>21)),"Priority 2","Monitor")) -> Monitor | Y8: =IF(COUNTA(A8:N8)=14,"OK","CHECK") -> OK
A9: =Raw_Data!A9 -> 4e265c34-103a-4dbb-9553-76c9aa47e946 | B9: =Raw_Data!B9 -> 56 | C9: =Raw_Data!C9 -> Other | D9: =Raw_Data!D9 -> Standard | E9: =Raw_Data!E9 -> 1.89 | F9: =Raw_Data!F9 -> 13 | G9: =Raw_Data!G9 -> Africa | H9: =Raw_Data!H9 -> Mobile | ... N9: =Raw_Data!N9 -> Action | O9: =IF(B9<25,"18-24",IF(B9<35,"25-34",IF(B9<45,"35-44",IF(B9<55,"45-54","55-70")))) -> 55-70 | P9: =IF(E9<10,"<10h",IF(E9<25,"10-24h",IF(E9<50,"25-49h","50h+"))) -> <10h | Q9: =IF(F9<=7,"0-7d",IF(F9<=21,"8-21d",IF(F9<=45,"22-45d","46-60d"))) -> 8-21d | R9: =IF(AND(E9>=25,F9<=21),"High",IF(OR(E9>=10,F9<=45),"Medium","Low")) -> Medium | S9: =IF(I9<10,"Low",IF(I9<16,"Mid","High")) -> Mid | T9: =IF(J9=1,"Churned","Active") -> Churned | U9: =1/(1+EXP(-(Predictive_Model!$B$5+((B9-Predictive_Model!$B$20)/Predictive_Model!$C$20)*Predictive_Model!$D$20+((E9-Predictive_Model!$B$21)/Predictive_Model!$C$21)*Predictive_Model!$D$21+((F9-Predictive_Model!$B$22)/Predictive_Model!$C$22)*Predictive_Model!$D$22+((I9-Predictive_Model!$B$23)/Predictive_Model!$C$23)*Predictive_Model!$D$23+((L9-Predictive_Model!$B$24)/Predictive_Model!$C$24)*Predictive_Model!$D$24+((M9-Predictive_Model!$B$25)/Predictive_Model!$C$25)*Predictive_Model!$D$25+IF(C9="Male",Predictive_Model!$D$31,IF(C9="Other",Predictive_Model!$D$32,0))+IF(D9="Premium",Predictive_Model!$D$34,IF(D9="Standard",Predictive_Model!$D$35,0))+IF(G9="Asia",Predictive_Model!$D$37,IF(G9="Europe",Predictive_Model!$D$38,IF(G9="North America",Predictive_Model!$D$39,IF(G9="Oceania",Predictive_Model!$D$40,IF(G9="South America",Predictive_Model!$D$41,0)))))+IF(H9="Laptop",Predictive_Model!$D$43,IF(H9="Mobile",Predictive_Model!$D$44,IF(H9="TV",Predictive_Model!$D$45,IF(H9="Tablet",Predictive_Model!$D$46,0))))+IF(K9="Crypto",Predictive_Model!$D$48,IF(K9="Debit Card",Predictive_Model!$D$49,IF(K9="Gift Card",Predictive_Model!$D$50,IF(K9="PayPal",Predictive_Model!$D$51,0))))+IF(N9="Comedy",Predictive_Model!$D$53,IF(N9="Documentary",Predictive_Model!$D$54,IF(N9="Drama",Predictive_Model!$D$55,IF(N9="Horror",Predictive_Model!$D$56,IF(N9="Romance",Predictive_Model!$D$57,IF(N9="Sci-Fi",Predictive_Model!$D$58,0))))))))) -> 0.99407467 | V9: =IF(U9>=0.75,"Critical",IF(U9>=0.5,"High",IF(U9>=0.25,"Medium","Low"))) -> Critical | W9: =IF(J9=1,I9,I9*U9) -> 13.99 | X9: =IF(AND(V9="Critical",I9>=15),"Priority 1",IF(OR(V9="Critical",AND(V9="High",F9>21)),"Priority 2","Monitor")) -> Priority 2 | Y9: =IF(COUNTA(A9:N9)=14,"OK","CHECK") -> OK
A10: =Raw_Data!A10 -> d8079475-5be7-47e9-8782-ceb7ff61395e | B10: =Raw_Data!B10 -> 58 | C10: =Raw_Data!C10 -> Female | D10: =Raw_Data!D10 -> Standard | E10: =Raw_Data!E10 -> 13.8 | F10: =Raw_Data!F10 -> 26 | G10: =Raw_Data!G10 -> Oceania | H10: =Raw_Data!H10 -> Mobile | ... N10: =Raw_Data!N10 -> Action | O10: =IF(B10<25,"18-24",IF(B10<35,"25-34",IF(B10<45,"35-44",IF(B10<55,"45-54","55-70")))) -> 55-70 | P10: =IF(E10<10,"<10h",IF(E10<25,"10-24h",IF(E10<50,"25-49h","50h+"))) -> 10-24h | Q10: =IF(F10<=7,"0-7d",IF(F10<=21,"8-21d",IF(F10<=45,"22-45d","46-60d"))) -> 22-45d | R10: =IF(AND(E10>=25,F10<=21),"High",IF(OR(E10>=10,F10<=45),"Medium","Low")) -> Medium | S10: =IF(I10<10,"Low",IF(I10<16,"Mid","High")) -> Mid | T10: =IF(J10=1,"Churned","Active") -> Active | U10: =1/(1+EXP(-(Predictive_Model!$B$5+((B10-Predictive_Model!$B$20)/Predictive_Model!$C$20)*Predictive_Model!$D$20+((E10-Predictive_Model!$B$21)/Predictive_Model!$C$21)*Predictive_Model!$D$21+((F10-Predictive_Model!$B$22)/Predictive_Model!$C$22)*Predictive_Model!$D$22+((I10-Predictive_Model!$B$23)/Predictive_Model!$C$23)*Predictive_Model!$D$23+((L10-Predictive_Model!$B$24)/Predictive_Model!$C$24)*Predictive_Model!$D$24+((M10-Predictive_Model!$B$25)/Predictive_Model!$C$25)*Predictive_Model!$D$25+IF(C10="Male",Predictive_Model!$D$31,IF(C10="Other",Predictive_Model!$D$32,0))+IF(D10="Premium",Predictive_Model!$D$34,IF(D10="Standard",Predictive_Model!$D$35,0))+IF(G10="Asia",Predictive_Model!$D$37,IF(G10="Europe",Predictive_Model!$D$38,IF(G10="North America",Predictive_Model!$D$39,IF(G10="Oceania",Predictive_Model!$D$40,IF(G10="South America",Predictive_Model!$D$41,0)))))+IF(H10="Laptop",Predictive_Model!$D$43,IF(H10="Mobile",Predictive_Model!$D$44,IF(H10="TV",Predictive_Model!$D$45,IF(H10="Tablet",Predictive_Model!$D$46,0))))+IF(K10="Crypto",Predictive_Model!$D$48,IF(K10="Debit Card",Predictive_Model!$D$49,IF(K10="Gift Card",Predictive_Model!$D$50,IF(K10="PayPal",Predictive_Model!$D$51,0))))+IF(N10="Comedy",Predictive_Model!$D$53,IF(N10="Documentary",Predictive_Model!$D$54,IF(N10="Drama",Predictive_Model!$D$55,IF(N10="Horror",Predictive_Model!$D$56,IF(N10="Romance",Predictive_Model!$D$57,IF(N10="Sci-Fi",Predictive_Model!$D$58,0))))))))) -> 0.8489476 | V10: =IF(U10>=0.75,"Critical",IF(U10>=0.5,"High",IF(U10>=0.25,"Medium","Low"))) -> Critical | W10: =IF(J10=1,I10,I10*U10) -> 11.876777 | X10: =IF(AND(V10="Critical",I10>=15),"Priority 1",IF(OR(V10="Critical",AND(V10="High",F10>21)),"Priority 2","Monitor")) -> Priority 2 | Y10: =IF(COUNTA(A10:N10)=14,"OK","CHECK") -> OK
A11: =Raw_Data!A11 -> 8e63450a-13d6-4e83-bbb5-6aebde9152cb | B11: =Raw_Data!B11 -> 48 | C11: =Raw_Data!C11 -> Other | D11: =Raw_Data!D11 -> Basic | E11: =Raw_Data!E11 -> 13.83 | F11: =Raw_Data!F11 -> 20 | G11: =Raw_Data!G11 -> Asia | H11: =Raw_Data!H11 -> TV | ... N11: =Raw_Data!N11 -> Romance | O11: =IF(B11<25,"18-24",IF(B11<35,"25-34",IF(B11<45,"35-44",IF(B11<55,"45-54","55-70")))) -> 45-54 | P11: =IF(E11<10,"<10h",IF(E11<25,"10-24h",IF(E11<50,"25-49h","50h+"))) -> 10-24h | Q11: =IF(F11<=7,"0-7d",IF(F11<=21,"8-21d",IF(F11<=45,"22-45d","46-60d"))) -> 8-21d | R11: =IF(AND(E11>=25,F11<=21),"High",IF(OR(E11>=10,F11<=45),"Medium","Low")) -> Medium | S11: =IF(I11<10,"Low",IF(I11<16,"Mid","High")) -> Low | T11: =IF(J11=1,"Churned","Active") -> Active | U11: =1/(1+EXP(-(Predictive_Model!$B$5+((B11-Predictive_Model!$B$20)/Predictive_Model!$C$20)*Predictive_Model!$D$20+((E11-Predictive_Model!$B$21)/Predictive_Model!$C$21)*Predictive_Model!$D$21+((F11-Predictive_Model!$B$22)/Predictive_Model!$C$22)*Predictive_Model!$D$22+((I11-Predictive_Model!$B$23)/Predictive_Model!$C$23)*Predictive_Model!$D$23+((L11-Predictive_Model!$B$24)/Predictive_Model!$C$24)*Predictive_Model!$D$24+((M11-Predictive_Model!$B$25)/Predictive_Model!$C$25)*Predictive_Model!$D$25+IF(C11="Male",Predictive_Model!$D$31,IF(C11="Other",Predictive_Model!$D$32,0))+IF(D11="Premium",Predictive_Model!$D$34,IF(D11="Standard",Predictive_Model!$D$35,0))+IF(G11="Asia",Predictive_Model!$D$37,IF(G11="Europe",Predictive_Model!$D$38,IF(G11="North America",Predictive_Model!$D$39,IF(G11="Oceania",Predictive_Model!$D$40,IF(G11="South America",Predictive_Model!$D$41,0)))))+IF(H11="Laptop",Predictive_Model!$D$43,IF(H11="Mobile",Predictive_Model!$D$44,IF(H11="TV",Predictive_Model!$D$45,IF(H11="Tablet",Predictive_Model!$D$46,0))))+IF(K11="Crypto",Predictive_Model!$D$48,IF(K11="Debit Card",Predictive_Model!$D$49,IF(K11="Gift Card",Predictive_Model!$D$50,IF(K11="PayPal",Predictive_Model!$D$51,0))))+IF(N11="Comedy",Predictive_Model!$D$53,IF(N11="Documentary",Predictive_Model!$D$54,IF(N11="Drama",Predictive_Model!$D$55,IF(N11="Horror",Predictive_Model!$D$56,IF(N11="Romance",Predictive_Model!$D$57,IF(N11="Sci-Fi",Predictive_Model!$D$58,0))))))))) -> 0.19342511 | V11: =IF(U11>=0.75,"Critical",IF(U11>=0.5,"High",IF(U11>=0.25,"Medium","Low"))) -> Low | W11: =IF(J11=1,I11,I11*U11) -> 1.7388917 | X11: =IF(AND(V11="Critical",I11>=15),"Priority 1",IF(OR(V11="Critical",AND(V11="High",F11>21)),"Priority 2","Monitor")) -> Monitor | Y11: =IF(COUNTA(A11:N11)=14,"OK","CHECK") -> OK
A12: =Raw_Data!A12 -> 02387681-8c42-462a-807a-de0168c73b38 | B12: =Raw_Data!B12 -> 51 | C12: =Raw_Data!C12 -> Male | D12: =Raw_Data!D12 -> Basic | E12: =Raw_Data!E12 -> 14.3 | F12: =Raw_Data!F12 -> 56 | G12: =Raw_Data!G12 -> Europe | H12: =Raw_Data!H12 -> Mobile | ... N12: =Raw_Data!N12 -> Action | O12: =IF(B12<25,"18-24",IF(B12<35,"25-34",IF(B12<45,"35-44",IF(B12<55,"45-54","55-70")))) -> 45-54 | P12: =IF(E12<10,"<10h",IF(E12<25,"10-24h",IF(E12<50,"25-49h","50h+"))) -> 10-24h | Q12: =IF(F12<=7,"0-7d",IF(F12<=21,"8-21d",IF(F12<=45,"22-45d","46-60d"))) -> 46-60d | R12: =IF(AND(E12>=25,F12<=21),"High",IF(OR(E12>=10,F12<=45),"Medium","Low")) -> Medium | S12: =IF(I12<10,"Low",IF(I12<16,"Mid","High")) -> Low | T12: =IF(J12=1,"Churned","Active") -> Churned | U12: =1/(1+EXP(-(Predictive_Model!$B$5+((B12-Predictive_Model!$B$20)/Predictive_Model!$C$20)*Predictive_Model!$D$20+((E12-Predictive_Model!$B$21)/Predictive_Model!$C$21)*Predictive_Model!$D$21+((F12-Predictive_Model!$B$22)/Predictive_Model!$C$22)*Predictive_Model!$D$22+((I12-Predictive_Model!$B$23)/Predictive_Model!$C$23)*Predictive_Model!$D$23+((L12-Predictive_Model!$B$24)/Predictive_Model!$C$24)*Predictive_Model!$D$24+((M12-Predictive_Model!$B$25)/Predictive_Model!$C$25)*Predictive_Model!$D$25+IF(C12="Male",Predictive_Model!$D$31,IF(C12="Other",Predictive_Model!$D$32,0))+IF(D12="Premium",Predictive_Model!$D$34,IF(D12="Standard",Predictive_Model!$D$35,0))+IF(G12="Asia",Predictive_Model!$D$37,IF(G12="Europe",Predictive_Model!$D$38,IF(G12="North America",Predictive_Model!$D$39,IF(G12="Oceania",Predictive_Model!$D$40,IF(G12="South America",Predictive_Model!$D$41,0)))))+IF(H12="Laptop",Predictive_Model!$D$43,IF(H12="Mobile",Predictive_Model!$D$44,IF(H12="TV",Predictive_Model!$D$45,IF(H12="Tablet",Predictive_Model!$D$46,0))))+IF(K12="Crypto",Predictive_Model!$D$48,IF(K12="Debit Card",Predictive_Model!$D$49,IF(K12="Gift Card",Predictive_Model!$D$50,IF(K12="PayPal",Predictive_Model!$D$51,0))))+IF(N12="Comedy",Predictive_Model!$D$53,IF(N12="Documentary",Predictive_Model!$D$54,IF(N12="Drama",Predictive_Model!$D$55,IF(N12="Horror",Predictive_Model!$D$56,IF(N12="Romance",Predictive_Model!$D$57,IF(N12="Sci-Fi",Predictive_Model!$D$58,0))))))))) -> 0.99988193 | V12: =IF(U12>=0.75,"Critical",IF(U12>=0.5,"High",IF(U12>=0.25,"Medium","Low"))) -> Critical | W12: =IF(J12=1,I12,I12*U12) -> 8.99 | X12: =IF(AND(V12="Critical",I12>=15),"Priority 1",IF(OR(V12="Critical",AND(V12="High",F12>21)),"Priority 2","Monitor")) -> Priority 2 | Y12: =IF(COUNTA(A12:N12)=14,"OK","CHECK") -> OK
A13: =Raw_Data!A13 -> 0bcaad0c-545c-4ee1-85a6-75e165f39361 | B13: =Raw_Data!B13 -> 45 | C13: =Raw_Data!C13 -> Other | D13: =Raw_Data!D13 -> Basic | E13: =Raw_Data!E13 -> 9.98 | F13: =Raw_Data!F13 -> 10 | G13: =Raw_Data!G13 -> Asia | H13: =Raw_Data!H13 -> Mobile | ... N13: =Raw_Data!N13 -> Romance | O13: =IF(B13<25,"18-24",IF(B13<35,"25-34",IF(B13<45,"35-44",IF(B13<55,"45-54","55-70")))) -> 45-54 | P13: =IF(E13<10,"<10h",IF(E13<25,"10-24h",IF(E13<50,"25-49h","50h+"))) -> <10h | Q13: =IF(F13<=7,"0-7d",IF(F13<=21,"8-21d",IF(F13<=45,"22-45d","46-60d"))) -> 8-21d | R13: =IF(AND(E13>=25,F13<=21),"High",IF(OR(E13>=10,F13<=45),"Medium","Low")) -> Medium | S13: =IF(I13<10,"Low",IF(I13<16,"Mid","High")) -> Low | T13: =IF(J13=1,"Churned","Active") -> Active | U13: =1/(1+EXP(-(Predictive_Model!$B$5+((B13-Predictive_Model!$B$20)/Predictive_Model!$C$20)*Predictive_Model!$D$20+((E13-Predictive_Model!$B$21)/Predictive_Model!$C$21)*Predictive_Model!$D$21+((F13-Predictive_Model!$B$22)/Predictive_Model!$C$22)*Predictive_Model!$D$22+((I13-Predictive_Model!$B$23)/Predictive_Model!$C$23)*Predictive_Model!$D$23+((L13-Predictive_Model!$B$24)/Predictive_Model!$C$24)*Predictive_Model!$D$24+((M13-Predictive_Model!$B$25)/Predictive_Model!$C$25)*Predictive_Model!$D$25+IF(C13="Male",Predictive_Model!$D$31,IF(C13="Other",Predictive_Model!$D$32,0))+IF(D13="Premium",Predictive_Model!$D$34,IF(D13="Standard",Predictive_Model!$D$35,0))+IF(G13="Asia",Predictive_Model!$D$37,IF(G13="Europe",Predictive_Model!$D$38,IF(G13="North America",Predictive_Model!$D$39,IF(G13="Oceania",Predictive_Model!$D$40,IF(G13="South America",Predictive_Model!$D$41,0)))))+IF(H13="Laptop",Predictive_Model!$D$43,IF(H13="Mobile",Predictive_Model!$D$44,IF(H13="TV",Predictive_Model!$D$45,IF(H13="Tablet",Predictive_Model!$D$46,0))))+IF(K13="Crypto",Predictive_Model!$D$48,IF(K13="Debit Card",Predictive_Model!$D$49,IF(K13="Gift Card",Predictive_Model!$D$50,IF(K13="PayPal",Predictive_Model!$D$51,0))))+IF(N13="Comedy",Predictive_Model!$D$53,IF(N13="Documentary",Predictive_Model!$D$54,IF(N13="Drama",Predictive_Model!$D$55,IF(N13="Horror",Predictive_Model!$D$56,IF(N13="Romance",Predictive_Model!$D$57,IF(N13="Sci-Fi",Predictive_Model!$D$58,0))))))))) -> 0.73134731 | V13: =IF(U13>=0.75,"Critical",IF(U13>=0.5,"High",IF(U13>=0.25,"Medium","Low"))) -> High | W13: =IF(J13=1,I13,I13*U13) -> 6.5748123 | X13: =IF(AND(V13="Critical",I13>=15),"Priority 1",IF(OR(V13="Critical",AND(V13="High",F13>21)),"Priority 2","Monitor")) -> Monitor | Y13: =IF(COUNTA(A13:N13)=14,"OK","CHECK") -> OK
A14: =Raw_Data!A14 -> eae6439e-8cdf-4258-ab49-c493925b927a | B14: =Raw_Data!B14 -> 32 | C14: =Raw_Data!C14 -> Other | D14: =Raw_Data!D14 -> Premium | E14: =Raw_Data!E14 -> 2.22 | F14: =Raw_Data!F14 -> 34 | G14: =Raw_Data!G14 -> Europe | H14: =Raw_Data!H14 -> TV | ... N14: =Raw_Data!N14 -> Drama | O14: =IF(B14<25,"18-24",IF(B14<35,"25-34",IF(B14<45,"35-44",IF(B14<55,"45-54","55-70")))) -> 25-34 | P14: =IF(E14<10,"<10h",IF(E14<25,"10-24h",IF(E14<50,"25-49h","50h+"))) -> <10h | Q14: =IF(F14<=7,"0-7d",IF(F14<=21,"8-21d",IF(F14<=45,"22-45d","46-60d"))) -> 22-45d | R14: =IF(AND(E14>=25,F14<=21),"High",IF(OR(E14>=10,F14<=45),"Medium","Low")) -> Medium | S14: =IF(I14<10,"Low",IF(I14<16,"Mid","High")) -> High | T14: =IF(J14=1,"Churned","Active") -> Churned | U14: =1/(1+EXP(-(Predictive_Model!$B$5+((B14-Predictive_Model!$B$20)/Predictive_Model!$C$20)*Predictive_Model!$D$20+((E14-Predictive_Model!$B$21)/Predictive_Model!$C$21)*Predictive_Model!$D$21+((F14-Predictive_Model!$B$22)/Predictive_Model!$C$22)*Predictive_Model!$D$22+((I14-Predictive_Model!$B$23)/Predictive_Model!$C$23)*Predictive_Model!$D$23+((L14-Predictive_Model!$B$24)/Predictive_Model!$C$24)*Predictive_Model!$D$24+((M14-Predictive_Model!$B$25)/Predictive_Model!$C$25)*Predictive_Model!$D$25+IF(C14="Male",Predictive_Model!$D$31,IF(C14="Other",Predictive_Model!$D$32,0))+IF(D14="Premium",Predictive_Model!$D$34,IF(D14="Standard",Predictive_Model!$D$35,0))+IF(G14="Asia",Predictive_Model!$D$37,IF(G14="Europe",Predictive_Model!$D$38,IF(G14="North America",Predictive_Model!$D$39,IF(G14="Oceania",Predictive_Model!$D$40,IF(G14="South America",Predictive_Model!$D$41,0)))))+IF(H14="Laptop",Predictive_Model!$D$43,IF(H14="Mobile",Predictive_Model!$D$44,IF(H14="TV",Predictive_Model!$D$45,IF(H14="Tablet",Predictive_Model!$D$46,0))))+IF(K14="Crypto",Predictive_Model!$D$48,IF(K14="Debit Card",Predictive_Model!$D$49,IF(K14="Gift Card",Predictive_Model!$D$50,IF(K14="PayPal",Predictive_Model!$D$51,0))))+IF(N14="Comedy",Predictive_Model!$D$53,IF(N14="Documentary",Predictive_Model!$D$54,IF(N14="Drama",Predictive_Model!$D$55,IF(N14="Horror",Predictive_Model!$D$56,IF(N14="Romance",Predictive_Model!$D$57,IF(N14="Sci-Fi",Predictive_Model!$D$58,0))))))))) -> 0.99187122 | V14: =IF(U14>=0.75,"Critical",IF(U14>=0.5,"High",IF(U14>=0.25,"Medium","Low"))) -> Critical | W14: =IF(J14=1,I14,I14*U14) -> 17.99 | X14: =IF(AND(V14="Critical",I14>=15),"Priority 1",IF(OR(V14="Critical",AND(V14="High",F14>21)),"Priority 2","Monitor")) -> Priority 1 | Y14: =IF(COUNTA(A14:N14)=14,"OK","CHECK") -> OK
A15: =Raw_Data!A15 -> 45a03ce3-26d0-4cd5-a9bd-22d42490b612 | B15: =Raw_Data!B15 -> 26 | C15: =Raw_Data!C15 -> Male | D15: =Raw_Data!D15 -> Premium | E15: =Raw_Data!E15 -> 15.42 | F15: =Raw_Data!F15 -> 36 | G15: =Raw_Data!G15 -> Asia | H15: =Raw_Data!H15 -> Laptop | ... N15: =Raw_Data!N15 -> Comedy | O15: =IF(B15<25,"18-24",IF(B15<35,"25-34",IF(B15<45,"35-44",IF(B15<55,"45-54","55-70")))) -> 25-34 | P15: =IF(E15<10,"<10h",IF(E15<25,"10-24h",IF(E15<50,"25-49h","50h+"))) -> 10-24h | Q15: =IF(F15<=7,"0-7d",IF(F15<=21,"8-21d",IF(F15<=45,"22-45d","46-60d"))) -> 22-45d | R15: =IF(AND(E15>=25,F15<=21),"High",IF(OR(E15>=10,F15<=45),"Medium","Low")) -> Medium | S15: =IF(I15<10,"Low",IF(I15<16,"Mid","High")) -> High | T15: =IF(J15=1,"Churned","Active") -> Active | U15: =1/(1+EXP(-(Predictive_Model!$B$5+((B15-Predictive_Model!$B$20)/Predictive_Model!$C$20)*Predictive_Model!$D$20+((E15-Predictive_Model!$B$21)/Predictive_Model!$C$21)*Predictive_Model!$D$21+((F15-Predictive_Model!$B$22)/Predictive_Model!$C$22)*Predictive_Model!$D$22+((I15-Predictive_Model!$B$23)/Predictive_Model!$C$23)*Predictive_Model!$D$23+((L15-Predictive_Model!$B$24)/Predictive_Model!$C$24)*Predictive_Model!$D$24+((M15-Predictive_Model!$B$25)/Predictive_Model!$C$25)*Predictive_Model!$D$25+IF(C15="Male",Predictive_Model!$D$31,IF(C15="Other",Predictive_Model!$D$32,0))+IF(D15="Premium",Predictive_Model!$D$34,IF(D15="Standard",Predictive_Model!$D$35,0))+IF(G15="Asia",Predictive_Model!$D$37,IF(G15="Europe",Predictive_Model!$D$38,IF(G15="North America",Predictive_Model!$D$39,IF(G15="Oceania",Predictive_Model!$D$40,IF(G15="South America",Predictive_Model!$D$41,0)))))+IF(H15="Laptop",Predictive_Model!$D$43,IF(H15="Mobile",Predictive_Model!$D$44,IF(H15="TV",Predictive_Model!$D$45,IF(H15="Tablet",Predictive_Model!$D$46,0))))+IF(K15="Crypto",Predictive_Model!$D$48,IF(K15="Debit Card",Predictive_Model!$D$49,IF(K15="Gift Card",Predictive_Model!$D$50,IF(K15="PayPal",Predictive_Model!$D$51,0))))+IF(N15="Comedy",Predictive_Model!$D$53,IF(N15="Documentary",Predictive_Model!$D$54,IF(N15="Drama",Predictive_Model!$D$55,IF(N15="Horror",Predictive_Model!$D$56,IF(N15="Romance",Predictive_Model!$D$57,IF(N15="Sci-Fi",Predictive_Model!$D$58,0))))))))) -> 0.11962546 | V15: =IF(U15>=0.75,"Critical",IF(U15>=0.5,"High",IF(U15>=0.25,"Medium","Low"))) -> Low | W15: =IF(J15=1,I15,I15*U15) -> 2.152062 | X15: =IF(AND(V15="Critical",I15>=15),"Priority 1",IF(OR(V15="Critical",AND(V15="High",F15>21)),"Priority 2","Monitor")) -> Monitor | Y15: =IF(COUNTA(A15:N15)=14,"OK","CHECK") -> OK
A16: =Raw_Data!A16 -> 9df43ad1-d6ee-44d0-a79b-c8ab444f10bf | B16: =Raw_Data!B16 -> 28 | C16: =Raw_Data!C16 -> Other | D16: =Raw_Data!D16 -> Standard | E16: =Raw_Data!E16 -> 22.26 | F16: =Raw_Data!F16 -> 38 | G16: =Raw_Data!G16 -> South America | H16: =Raw_Data!H16 -> Mobile | ... N16: =Raw_Data!N16 -> Horror | O16: =IF(B16<25,"18-24",IF(B16<35,"25-34",IF(B16<45,"35-44",IF(B16<55,"45-54","55-70")))) -> 25-34 | P16: =IF(E16<10,"<10h",IF(E16<25,"10-24h",IF(E16<50,"25-49h","50h+"))) -> 10-24h | Q16: =IF(F16<=7,"0-7d",IF(F16<=21,"8-21d",IF(F16<=45,"22-45d","46-60d"))) -> 22-45d | R16: =IF(AND(E16>=25,F16<=21),"High",IF(OR(E16>=10,F16<=45),"Medium","Low")) -> Medium | S16: =IF(I16<10,"Low",IF(I16<16,"Mid","High")) -> Mid | T16: =IF(J16=1,"Churned","Active") -> Active | U16: =1/(1+EXP(-(Predictive_Model!$B$5+((B16-Predictive_Model!$B$20)/Predictive_Model!$C$20)*Predictive_Model!$D$20+((E16-Predictive_Model!$B$21)/Predictive_Model!$C$21)*Predictive_Model!$D$21+((F16-Predictive_Model!$B$22)/Predictive_Model!$C$22)*Predictive_Model!$D$22+((I16-Predictive_Model!$B$23)/Predictive_Model!$C$23)*Predictive_Model!$D$23+((L16-Predictive_Model!$B$24)/Predictive_Model!$C$24)*Predictive_Model!$D$24+((M16-Predictive_Model!$B$25)/Predictive_Model!$C$25)*Predictive_Model!$D$25+IF(C16="Male",Predictive_Model!$D$31,IF(C16="Other",Predictive_Model!$D$32,0))+IF(D16="Premium",Predictive_Model!$D$34,IF(D16="Standard",Predictive_Model!$D$35,0))+IF(G16="Asia",Predictive_Model!$D$37,IF(G16="Europe",Predictive_Model!$D$38,IF(G16="North America",Predictive_Model!$D$39,IF(G16="Oceania",Predictive_Model!$D$40,IF(G16="South America",Predictive_Model!$D$41,0)))))+IF(H16="Laptop",Predictive_Model!$D$43,IF(H16="Mobile",Predictive_Model!$D$44,IF(H16="TV",Predictive_Model!$D$45,IF(H16="Tablet",Predictive_Model!$D$46,0))))+IF(K16="Crypto",Predictive_Model!$D$48,IF(K16="Debit Card",Predictive_Model!$D$49,IF(K16="Gift Card",Predictive_Model!$D$50,IF(K16="PayPal",Predictive_Model!$D$51,0))))+IF(N16="Comedy",Predictive_Model!$D$53,IF(N16="Documentary",Predictive_Model!$D$54,IF(N16="Drama",Predictive_Model!$D$55,IF(N16="Horror",Predictive_Model!$D$56,IF(N16="Romance",Predictive_Model!$D$57,IF(N16="Sci-Fi",Predictive_Model!$D$58,0))))))))) -> 0.26694948 | V16: =IF(U16>=0.75,"Critical",IF(U16>=0.5,"High",IF(U16>=0.25,"Medium","Low"))) -> Medium | W16: =IF(J16=1,I16,I16*U16) -> 3.7346232 | X16: =IF(AND(V16="Critical",I16>=15),"Priority 1",IF(OR(V16="Critical",AND(V16="High",F16>21)),"Priority 2","Monitor")) -> Monitor | Y16: =IF(COUNTA(A16:N16)=14,"OK","CHECK") -> OK
... A5004: =Raw_Data!A5004 -> 82aeef39-ddb0-40ad-bae1-5c436e0cf042 | B5004: =Raw_Data!B5004 -> 57 | C5004: =Raw_Data!C5004 -> Male | D5004: =Raw_Data!D5004 -> Basic | E5004: =Raw_Data!E5004 -> 1.62 | F5004: =Raw_Data!F5004 -> 17 | G5004: =Raw_Data!G5004 -> Africa | H5004: =Raw_Data!H5004 -> Mobile | ... N5004: =Raw_Data!N5004 -> Action | O5004: =IF(B5004<25,"18-24",IF(B5004<35,"25-34",IF(B5004<45,"35-44",IF(B5004<55,"45-54","55-70")))) -> 55-70 | P5004: =IF(E5004<10,"<10h",IF(E5004<25,"10-24h",IF(E5004<50,"25-49h","50h+"))) -> <10h | Q5004: =IF(F5004<=7,"0-7d",IF(F5004<=21,"8-21d",IF(F5004<=45,"22-45d","46-60d"))) -> 8-21d | R5004: =IF(AND(E5004>=25,F5004<=21),"High",IF(OR(E5004>=10,F5004<=45),"Medium","Low")) -> Medium | S5004: =IF(I5004<10,"Low",IF(I5004<16,"Mid","High")) -> Low | T5004: =IF(J5004=1,"Churned","Active") -> Churned | U5004: =1/(1+EXP(-(Predictive_Model!$B$5+((B5004-Predictive_Model!$B$20)/Predictive_Model!$C$20)*Predictive_Model!$D$20+((E5004-Predictive_Model!$B$21)/Predictive_Model!$C$21)*Predictive_Model!$D$21+((F5004-Predictive_Model!$B$22)/Predictive_Model!$C$22)*Predictive_Model!$D$22+((I5004-Predictive_Model!$B$23)/Predictive_Model!$C$23)*Predictive_Model!$D$23+((L5004-Predictive_Model!$B$24)/Predictive_Model!$C$24)*Predictive_Model!$D$24+((M5004-Predictive_Model!$B$25)/Predictive_Model!$C$25)*Predictive_Model!$D$25+IF(C5004="Male",Predictive_Model!$D$31,IF(C5004="Other",Predictive_Model!$D$32,0))+IF(D5004="Premium",Predictive_Model!$D$34,IF(D5004="Standard",Predictive_Model!$D$35,0))+IF(G5004="Asia",Predictive_Model!$D$37,IF(G5004="Europe",Predictive_Model!$D$38,IF(G5004="North America",Predictive_Model!$D$39,IF(G5004="Oceania",Predictive_Model!$D$40,IF(G5004="South America",Predictive_Model!$D$41,0)))))+IF(H5004="Laptop",Predictive_Model!$D$43,IF(H5004="Mobile",Predictive_Model!$D$44,IF(H5004="TV",Predictive_Model!$D$45,IF(H5004="Tablet",Predictive_Model!$D$46,0))))+IF(K5004="Crypto",Predictive_Model!$D$48,IF(K5004="Debit Card",Predictive_Model!$D$49,IF(K5004="Gift Card",Predictive_Model!$D$50,IF(K5004="PayPal",Predictive_Model!$D$51,0))))+IF(N5004="Comedy",Predictive_Model!$D$53,IF(N5004="Documentary",Predictive_Model!$D$54,IF(N5004="Drama",Predictive_Model!$D$55,IF(N5004="Horror",Predictive_Model!$D$56,IF(N5004="Romance",Predictive_Model!$D$57,IF(N5004="Sci-Fi",Predictive_Model!$D$58,0))))))))) -> 0.9990577 | V5004: =IF(U5004>=0.75,"Critical",IF(U5004>=0.5,"High",IF(U5004>=0.25,"Medium","Low"))) -> Critical | W5004: =IF(J5004=1,I5004,I5004*U5004) -> 8.99 | X5004: =IF(AND(V5004="Critical",I5004>=15),"Priority 1",IF(OR(V5004="Critical",AND(V5004="High",F5004>21)),"Priority 2","Monitor")) -> Priority 2 | Y5004: =IF(COUNTA(A5004:N5004)=14,"OK","CHECK") -> OK

Sheet Predictive_Model
A1: PREDICTIVE MODEL — LOGISTIC REGRESSION
A2: Model parameters estimated in Python, scoring executed in Excel with transparent formulas.
A4: MODEL PERFORMANCE
A5: Accuracy | B5: 0.8896 | D5: Intercept | E5: -1.4277247
A6: Precision | B6: 0.88540031
A7: Recall | B7: 0.89666137
A8: F1 | B8: 0.89099526
A9: ROC AUC | B9: 0.96509553
A18: STANDARDIZATION PARAMETERS
A19: Feature | B19: Mean | C19: Std Dev | D19: Coefficient
A20: age | B20: 43.5808 | C20: 15.52238 | D20: 0.0038614506
A21: watch_hours | B21: 11.627069 | C21: 11.815527 | D21: -3.7363528
A22: last_login_days | B22: 30.066933 | C22: 17.614208 | D22: 2.3440471
A23: monthly_fee | B23: 13.683067 | C23: 3.7000079 | D23: -0.79400525
A24: number_of_profiles | B24: 3.0202667 | C24: 1.4101026 | D24: -1.1011242
A25: avg_watch_time_per_day | B25: 0.88556267 | C25: 2.77306 | D25: -4.6934714
A29: CATEGORICAL COEFFICIENTS
A30: Variable | B30: Category | C30: Coefficient | D30: Baseline
A31: gender | B31: Male | C31: -0.13767217 | D31: -0.13767217
A32: gender | B32: Other | C32: -0.13472404 | D32: -0.13472404
A33: subscription_type | B33: Premium | C33: -0.18585464 | D33: -0.18585464
A34: subscription_type | B34: Standard | C34: -1.0245471 | D34: -1.0245471
A35: region | B35: Asia | C35: -0.088004436 | D35: -0.088004436
A36: region | B36: Europe | C36: 0.12672886 | D36: 0.12672886
A37: region | B37: North America | C37: -0.1175067 | D37: -0.1175067
A38: region | B38: Oceania | C38: 0.013434058 | D38: 0.013434058
A39: region | B39: South America | C39: 0.08720077 | D39: 0.08720077
A40: device | B40: Laptop | C40: 0.16570817 | D40: 0.16570817
A41: device | B41: Mobile | C41: 0.076147821 | D41: 0.076147821
A42: device | B42: TV | C42: 0.12540866 | D42: 0.12540866
... A53: favorite_genre | B53: Sci-Fi | C53: -0.039995448 | D53: -0.039995448
A60: CONFUSION MATRIX — HOLDOUT TEST SET
B61: Predicted Active | C61: Predicted Churn
A62: Actual Active | B62: 548 | C62: 73
A63: Actual Churn | B63: 65 | C63: 564
A66: MODEL INTERPRETATION
A67: Positive coefficient → higher log-odds of churn, holding other variables constant.
A68: Negative coefficient → lower log-odds of churn, holding other variables constant.
A69: Excel probability = 1 / (1 + EXP(-logit)).
A70: The workbook exposes the coefficients and standardization parameters so the scoring is auditable rather than a black box.
...

Sheet Churn_Analysis
A1: CHURN ANALYSIS
A2: Dimension-level analysis using COUNTIF(S), AVERAGEIF(S), SUMIF(S) and formula-driven rates.
A4: SUBSCRIPTION TYPE
A5: Segment | B5: Customers | C5: Churned | D5: Churn Rate | E5: Avg Watch Hrs | F5: Avg Last Login | G5: Revenue at Risk
A6: Basic | B6: =COUNTIF(Analysis_Data!$D$5:$D$5004,A6) -> 1661 | C6: =COUNTIFS(Analysis_Data!$D$5:$D$5004,A6,Analysis_Data!$J$5:$J$5004,1) -> 1027 | D6: =IFERROR(C6/B6,0) -> 0.61830223 | E6: =AVERAGEIF(Analysis_Data!$D$5:$D$5004,A6,Analysis_Data!$E$5:$E$5004) -> 11.563528 | F6: =AVERAGEIF(Analysis_Data!$D$5:$D$5004,A6,Analysis_Data!$F$5:$F$5004) -> 30.116195 | G6: =SUMIF(Analysis_Data!$D$5:$D$5004,A6,Analysis_Data!$W$5:$W$5004) -> 11393.407
A7: Standard | B7: =COUNTIF(Analysis_Data!$D$5:$D$5004,A7) -> 1646 | C7: =COUNTIFS(Analysis_Data!$D$5:$D$5004,A7,Analysis_Data!$J$5:$J$5004,1) -> 748 | D7: =IFERROR(C7/B7,0) -> 0.45443499 | E7: =AVERAGEIF(Analysis_Data!$D$5:$D$5004,A7,Analysis_Data!$E$5:$E$5004) -> 11.677491 | F7: =AVERAGEIF(Analysis_Data!$D$5:$D$5004,A7,Analysis_Data!$F$5:$F$5004) -> 30.068651 | G7: =SUMIF(Analysis_Data!$D$5:$D$5004,A7,Analysis_Data!$W$5:$W$5004) -> 16097.571
A8: Premium | B8: =COUNTIF(Analysis_Data!$D$5:$D$5004,A8) -> 1693 | C8: =COUNTIFS(Analysis_Data!$D$5:$D$5004,A8,Analysis_Data!$J$5:$J$5004,1) -> 740 | D8: =IFERROR(C8/B8,0) -> 0.43709392 | E8: =AVERAGEIF(Analysis_Data!$D$5:$D$5004,A8,Analysis_Data!$E$5:$E$5004) -> 11.706486 | F8: =AVERAGEIF(Analysis_Data!$D$5:$D$5004,A8,Analysis_Data!$F$5:$F$5004) -> 30.084465 | G8: =SUMIF(Analysis_Data!$D$5:$D$5004,A8,Analysis_Data!$W$5:$W$5004) -> 18088.08
A11: PAYMENT METHOD
A12: Segment | B12: Customers | C12: Churned | D12: Churn Rate | E12: Avg Watch Hrs | F12: Avg Last Login | G12: Revenue at Risk
A13: Credit Card | B13: =COUNTIF(Analysis_Data!$K$5:$K$5004,A13) -> 973 | C13: =COUNTIFS(Analysis_Data!$K$5:$K$5004,A13,Analysis_Data!$J$5:$J$5004,1) -> 424 | D13: =IFERROR(C13/B13,0) -> 0.43576567 | E13: =AVERAGEIF(Analysis_Data!$K$5:$K$5004,A13,Analysis_Data!$E$5:$E$5004) -> 11.820493 | F13: =AVERAGEIF(Analysis_Data!$K$5:$K$5004,A13,Analysis_Data!$F$5:$F$5004) -> 29.29702 | G13: =SUMIF(Analysis_Data!$K$5:$K$5004,A13,Analysis_Data!$W$5:$W$5004) -> 8444.6939
A14: Crypto | B14: =COUNTIF(Analysis_Data!$K$5:$K$5004,A14) -> 995 | C14: =COUNTIFS(Analysis_Data!$K$5:$K$5004,A14,Analysis_Data!$J$5:$J$5004,1) -> 594 | D14: =IFERROR(C14/B14,0) -> 0.59698492 | E14: =AVERAGEIF(Analysis_Data!$K$5:$K$5004,A14,Analysis_Data!$E$5:$E$5004) -> 11.562834 | F14: =AVERAGEIF(Analysis_Data!$K$5:$K$5004,A14,Analysis_Data!$F$5:$F$5004) -> 30.566834 | G14: =SUMIF(Analysis_Data!$K$5:$K$5004,A14,Analysis_Data!$W$5:$W$5004) -> 9601.3091
A15: Debit Card | B15: =COUNTIF(Analysis_Data!$K$5:$K$5004,A15) -> 1030 | C15: =COUNTIFS(Analysis_Data!$K$5:$K$5004,A15,Analysis_Data!$J$5:$J$5004,1) -> 450 | D15: =IFERROR(C15/B15,0) -> 0.4368932 | E15: =AVERAGEIF(Analysis_Data!$K$5:$K$5004,A15,Analysis_Data!$E$5:$E$5004) -> 11.795544 | F15: =AVERAGEIF(Analysis_Data!$K$5:$K$5004,A15,Analysis_Data!$F$5:$F$5004) -> 29.660194 | G15: =SUMIF(Analysis_Data!$K$5:$K$5004,A15,Analysis_Data!$W$5:$W$5004) -> 8958.4545
A16: Gift Card | B16: =COUNTIF(Analysis_Data!$K$5:$K$5004,A16) -> 976 | C16: =COUNTIFS(Analysis_Data!$K$5:$K$5004,A16,Analysis_Data!$J$5:$J$5004,1) -> 564 | D16: =IFERROR(C16/B16,0) -> 0.57786885 | E16: =AVERAGEIF(Analysis_Data!$K$5:$K$5004,A16,Analysis_Data!$E$5:$E$5004) -> 11.635512 | F16: =AVERAGEIF(Analysis_Data!$K$5:$K$5004,A16,Analysis_Data!$F$5:$F$5004) -> 30.853484 | G16: =SUMIF(Analysis_Data!$K$5:$K$5004,A16,Analysis_Data!$W$5:$W$5004) -> 9359.8428
A17: PayPal | B17: =COUNTIF(Analysis_Data!$K$5:$K$5004,A17) -> 1026 | C17: =COUNTIFS(Analysis_Data!$K$5:$K$5004,A17,Analysis_Data!$J$5:$J$5004,1) -> 483 | D17: =IFERROR(C17/B17,0) -> 0.47076023 | E17: =AVERAGEIF(Analysis_Data!$K$5:$K$5004,A17,Analysis_Data!$E$5:$E$5004) -> 11.437836 | F17: =AVERAGEIF(Analysis_Data!$K$5:$K$5004,A17,Analysis_Data!$F$5:$F$5004) -> 30.083821 | G17: =SUMIF(Analysis_Data!$K$5:$K$5004,A17,Analysis_Data!$W$5:$W$5004) -> 9214.7578
A20: REGION
A21: Segment | B21: Customers | C21: Churned | D21: Churn Rate | E21: Avg Watch Hrs | F21: Avg Last Login | G21: Revenue at Risk
A22: Africa | B22: =COUNTIF(Analysis_Data!$G$5:$G$5004,A22) -> 803 | C22: =COUNTIFS(Analysis_Data!$G$5:$G$5004,A22,Analysis_Data!$J$5:$J$5004,1) -> 388 | D22: =IFERROR(C22/B22,0) -> 0.48318804 | E22: =AVERAGEIF(Analysis_Data!$G$5:$G$5004,A22,Analysis_Data!$E$5:$E$5004) -> 11.667833 | F22: =AVERAGEIF(Analysis_Data!$G$5:$G$5004,A22,Analysis_Data!$F$5:$F$5004) -> 29.251557 | G22: =SUMIF(Analysis_Data!$G$5:$G$5004,A22,Analysis_Data!$W$5:$W$5004) -> 7088.0365
A23: Asia | B23: =COUNTIF(Analysis_Data!$G$5:$G$5004,A23) -> 841 | C23: =COUNTIFS(Analysis_Data!$G$5:$G$5004,A23,Analysis_Data!$J$5:$J$5004,1) -> 426 | D23: =IFERROR(C23/B23,0) -> 0.50653983 | E23: =AVERAGEIF(Analysis_Data!$G$5:$G$5004,A23,Analysis_Data!$E$5:$E$5004) -> 11.282652 | F23: =AVERAGEIF(Analysis_Data!$G$5:$G$5004,A23,Analysis_Data!$F$5:$F$5004) -> 30.136742 | G23: =SUMIF(Analysis_Data!$G$5:$G$5004,A23,Analysis_Data!$W$5:$W$5004) -> 7647.855
A24: Europe | B24: =COUNTIF(Analysis_Data!$G$5:$G$5004,A24) -> 867 | C24: =COUNTIFS(Analysis_Data!$G$5:$G$5004,A24,Analysis_Data!$J$5:$J$5004,1) -> 448 | D24: =IFERROR(C24/B24,0) -> 0.51672434 | E24: =AVERAGEIF(Analysis_Data!$G$5:$G$5004,A24,Analysis_Data!$E$5:$E$5004) -> 11.418858 | F24: =AVERAGEIF(Analysis_Data!$G$5:$G$5004,A24,Analysis_Data!$F$5:$F$5004) -> 30.547866 | G24: =SUMIF(Analysis_Data!$G$5:$G$5004,A24,Analysis_Data!$W$5:$W$5004) -> 7888.5773
A25: North America | B25: =COUNTIF(Analysis_Data!$G$5:$G$5004,A25) -> 851 | C25: =COUNTIFS(Analysis_Data!$G$5:$G$5004,A25,Analysis_Data!$J$5:$J$5004,1) -> 421 | D25: =IFERROR(C25/B25,0) -> 0.4947121 | E25: =AVERAGEIF(Analysis_Data!$G$5:$G$5004,A25,Analysis_Data!$E$5:$E$5004) -> 11.936557 | F25: =AVERAGEIF(Analysis_Data!$G$5:$G$5004,A25,Analysis_Data!$F$5:$F$5004) -> 30.882491 | G25: =SUMIF(Analysis_Data!$G$5:$G$5004,A25,Analysis_Data!$W$5:$W$5004) -> 7805.089
A26: Oceania | B26: =COUNTIF(Analysis_Data!$G$5:$G$5004,A26) -> 765 | C26: =COUNTIFS(Analysis_Data!$G$5:$G$5004,A26,Analysis_Data!$J$5:$J$5004,1) -> 383 | D26: =IFERROR(C26/B26,0) -> 0.50065359 | E26: =AVERAGEIF(Analysis_Data!$G$5:$G$5004,A26,Analysis_Data!$E$5:$E$5004) -> 11.743111 | F26: =AVERAGEIF(Analysis_Data!$G$5:$G$5004,A26,Analysis_Data!$F$5:$F$5004) -> 29.237908 | G26: =SUMIF(Analysis_Data!$G$5:$G$5004,A26,Analysis_Data!$W$5:$W$5004) -> 7225.5907
A27: South America | B27: =COUNTIF(Analysis_Data!$G$5:$G$5004,A27) -> 873 | C27: =COUNTIFS(Analysis_Data!$G$5:$G$5004,A27,Analysis_Data!$J$5:$J$5004,1) -> 449 | D27: =IFERROR(C27/B27,0) -> 0.51431844 | E27: =AVERAGEIF(Analysis_Data!$G$5:$G$5004,A27,Analysis_Data!$E$5:$E$5004) -> 11.852955 | F27: =AVERAGEIF(Analysis_Data!$G$5:$G$5004,A27,Analysis_Data!$F$5:$F$5004) -> 30.334479 | G27: =SUMIF(Analysis_Data!$G$5:$G$5004,A27,Analysis_Data!$W$5:$W$5004) -> 7923.9095
A30: DEVICE
A31: Segment | B31: Customers | C31: Churned | D31: Churn Rate | E31: Avg Watch Hrs | F31: Avg Last Login | G31: Revenue at Risk
A32: Desktop | B32: =COUNTIF(Analysis_Data!$H$5:$H$5004,A32) -> 949 | C32: =COUNTIFS(Analysis_Data!$H$5:$H$5004,A32,Analysis_Data!$J$5:$J$5004,1) -> 467 | D32: =IFERROR(C32/B32,0) -> 0.49209694 | E32: =AVERAGEIF(Analysis_Data!$H$5:$H$5004,A32,Analysis_Data!$E$5:$E$5004) -> 12.382603 | F32: =AVERAGEIF(Analysis_Data!$H$5:$H$5004,A32,Analysis_Data!$F$5:$F$5004) -> 30.982086 | G32: =SUMIF(Analysis_Data!$H$5:$H$5004,A32,Analysis_Data!$W$5:$W$5004) -> 8312.3439
A33: Laptop | B33: =COUNTIF(Analysis_Data!$H$5:$H$5004,A33) -> 1006 | C33: =COUNTIFS(Analysis_Data!$H$5:$H$5004,A33,Analysis_Data!$J$5:$J$5004,1) -> 521 | D33: =IFERROR(C33/B33,0) -> 0.51789264 | E33: =AVERAGEIF(Analysis_Data!$H$5:$H$5004,A33,Analysis_Data!$E$5:$E$5004) -> 11.2734 | F33: =AVERAGEIF(Analysis_Data!$H$5:$H$5004,A33,Analysis_Data!$F$5:$F$5004) -> 29.777336 | G33: =SUMIF(Analysis_Data!$H$5:$H$5004,A33,Analysis_Data!$W$5:$W$5004) -> 8775.4175
A34: Mobile | B34: =COUNTIF(Analysis_Data!$H$5:$H$5004,A34) -> 1004 | C34: =COUNTIFS(Analysis_Data!$H$5:$H$5004,A34,Analysis_Data!$J$5:$J$5004,1) -> 507 | D34: =IFERROR(C34/B34,0) -> 0.50498008 | E34: =AVERAGEIF(Analysis_Data!$H$5:$H$5004,A34,Analysis_Data!$E$5:$E$5004) -> 11.961116 | F34: =AVERAGEIF(Analysis_Data!$H$5:$H$5004,A34,Analysis_Data!$F$5:$F$5004) -> 30.138446 | G34: =SUMIF(Analysis_Data!$H$5:$H$5004,A34,Analysis_Data!$W$5:$W$5004) -> 9846.1275
A35: TV | B35: =COUNTIF(Analysis_Data!$H$5:$H$5004,A35) -> 993 | C35: =COUNTIFS(Analysis_Data!$H$5:$H$5004,A35,Analysis_Data!$J$5:$J$5004,1) -> 496 | D35: =IFERROR(C35/B35,0) -> 0.49949648 | E35: =AVERAGEIF(Analysis_Data!$H$5:$H$5004,A35,Analysis_Data!$E$5:$E$5004) -> 11.883202 | F35: =AVERAGEIF(Analysis_Data!$H$5:$H$5004,A35,Analysis_Data!$F$5:$F$5004) -> 29.969789 | G35: =SUMIF(Analysis_Data!$H$5:$H$5004,A35,Analysis_Data!$W$5:$W$5004) -> 8413.0973
A36: Tablet | B36: =COUNTIF(Analysis_Data!$H$5:$H$5004,A36) -> 1048 | C36: =COUNTIFS(Analysis_Data!$H$5:$H$5004,A36,Analysis_Data!$J$5:$J$5004,1) -> 524 | D36: =IFERROR(C36/B36,0) -> 0.5 | E36: =AVERAGEIF(Analysis_Data!$H$5:$H$5004,A36,Analysis_Data!$E$5:$E$5004) -> 10.826469 | F36: =AVERAGEIF(Analysis_Data!$H$5:$H$5004,A36,Analysis_Data!$F$5:$F$5004) -> 29.648855 | G36: =SUMIF(Analysis_Data!$H$5:$H$5004,A36,Analysis_Data!$W$5:$W$5004) -> 10232.072
A40: FAVORITE GENRE
A41: Segment | B41: Customers | C41: Churned | D41: Churn Rate | E41: Avg Watch Hrs | F41: Avg Last Login | G41: Revenue at Risk
A42: Action | B42: =COUNTIF(Analysis_Data!$N$5:$N$5004,A42) -> 697 | C42: =COUNTIFS(Analysis_Data!$N$5:$N$5004,A42,Analysis_Data!$J$5:$J$5004,1) -> 365 | D42: =IFERROR(C42/B42,0) -> 0.52367288 | E42: =AVERAGEIF(Analysis_Data!$N$5:$N$5004,A42,Analysis_Data!$E$5:$E$5004) -> 10.917532 | F42: =AVERAGEIF(Analysis_Data!$N$5:$N$5004,A42,Analysis_Data!$F$5:$F$5004) -> 30.061693 | G42: =SUMIF(Analysis_Data!$N$5:$N$5004,A42,Analysis_Data!$W$5:$W$5004) -> 6455.1736
A43: Comedy | B43: =COUNTIF(Analysis_Data!$N$5:$N$5004,A43) -> 685 | C43: =COUNTIFS(Analysis_Data!$N$5:$N$5004,A43,Analysis_Data!$J$5:$J$5004,1) -> 342 | D43: =IFERROR(C43/B43,0) -> 0.49927007 | E43: =AVERAGEIF(Analysis_Data!$N$5:$N$5004,A43,Analysis_Data!$E$5:$E$5004) -> 12.148175 | F43: =AVERAGEIF(Analysis_Data!$N$5:$N$5004,A43,Analysis_Data!$F$5:$F$5004) -> 30.127007 | G43: =SUMIF(Analysis_Data!$N$5:$N$5004,A43,Analysis_Data!$W$5:$W$5004) -> 6160.4251
A44: Documentary | B44: =COUNTIF(Analysis_Data!$N$5:$N$5004,A44) -> 729 | C44: =COUNTIFS(Analysis_Data!$N$5:$N$5004,A44,Analysis_Data!$J$5:$J$5004,1) -> 370 | D44: =IFERROR(C44/B44,0) -> 0.50754458 | E44: =AVERAGEIF(Analysis_Data!$N$5:$N$5004,A44,Analysis_Data!$E$5:$E$5004) -> 11.434005 | F44: =AVERAGEIF(Analysis_Data!$N$5:$N$5004,A44,Analysis_Data!$F$5:$F$5004) -> 30.928669 | G44: =SUMIF(Analysis_Data!$N$5:$N$5004,A44,Analysis_Data!$W$5:$W$5004) -> 6767.2551
A45: Drama | B45: =COUNTIF(Analysis_Data!$N$5:$N$5004,A45) -> 731 | C45: =COUNTIFS(Analysis_Data!$N$5:$N$5004,A45,Analysis_Data!$J$5:$J$5004,1) -> 382 | D45: =IFERROR(C45/B45,0) -> 0.52257182 | E45: =AVERAGEIF(Analysis_Data!$N$5:$N$5004,A45,Analysis_Data!$E$5:$E$5004) -> 11.642517 | F45: =AVERAGEIF(Analysis_Data!$N$5:$N$5004,A45,Analysis_Data!$F$5:$F$5004) -> 30.154583 | G45: =SUMIF(Analysis_Data!$N$5:$N$5004,A45,Analysis_Data!$W$5:$W$5004) -> 6763.6771
A46: Horror | B46: =COUNTIF(Analysis_Data!$N$5:$N$5004,A46) -> 713 | C46: =COUNTIFS(Analysis_Data!$N$5:$N$5004,A46,Analysis_Data!$J$5:$J$5004,1) -> 367 | D46: =IFERROR(C46/B46,0) -> 0.51472651 | E46: =AVERAGEIF(Analysis_Data!$N$5:$N$5004,A46,Analysis_Data!$E$5:$E$5004) -> 11.047994 | F46: =AVERAGEIF(Analysis_Data!$N$5:$N$5004,A46,Analysis_Data!$F$5:$F$5004) -> 30.26087 | G46: =SUMIF(Analysis_Data!$N$5:$N$5004,A46,Analysis_Data!$W$5:$W$5004) -> 6712.6722
A47: Romance | B47: =COUNTIF(Analysis_Data!$N$5:$N$5004,A47) -> 725 | C47: =COUNTIFS(Analysis_Data!$N$5:$N$5004,A47,Analysis_Data!$J$5:$J$5004,1) -> 350 | D47: =IFERROR(C47/B47,0) -> 0.48275862 | E47: =AVERAGEIF(Analysis_Data!$N$5:$N$5004,A47,Analysis_Data!$E$5:$E$5004) -> 12.736386 | F47: =AVERAGEIF(Analysis_Data!$N$5:$N$5004,A47,Analysis_Data!$F$5:$F$5004) -> 30.452414 | G47: =SUMIF(Analysis_Data!$N$5:$N$5004,A47,Analysis_Data!$W$5:$W$5004) -> 6381.5063
A48: Sci-Fi | B48: =COUNTIF(Analysis_Data!$N$5:$N$5004,A48) -> 720 | C48: =COUNTIFS(Analysis_Data!$N$5:$N$5004,A48,Analysis_Data!$J$5:$J$5004,1) -> 339 | D48: =IFERROR(C48/B48,0) -> 0.47083333 | E48: =AVERAGEIF(Analysis_Data!$N$5:$N$5004,A48,Analysis_Data!$E$5:$E$5004) -> 11.609806 | F48: =AVERAGEIF(Analysis_Data!$N$5:$N$5004,A48,Analysis_Data!$F$5:$F$5004) -> 28.631944 | G48: =SUMIF(Analysis_Data!$N$5:$N$5004,A48,Analysis_Data!$W$5:$W$5004) -> 6338.3486
A51: AGE BAND
A52: Segment | B52: Customers | C52: Churned | D52: Churn Rate | E52: Avg Watch Hrs | F52: Avg Last Login | G52: Revenue at Risk
...

Sheet Customer_Segments
A1: CUSTOMER SEGMENTATION
A2: Behavioral segmentation using formula-driven engagement, recency and predicted churn risk.
A4: SEGMENT SUMMARY
A5: Segment | B5: Definition | C5: Customers | D5: Churn Rate | E5: Avg Watch Hrs | F5: Avg Last Login | G5: Avg Risk | H5: Revenue at Risk
A6: Champions | B6: High engagement + recent login + low/medium risk | C6: =COUNTIFS(Analysis_Data!$R$5:$R$5004,"High",Analysis_Data!$Q$5:$Q$5004,"0-7d",Analysis_Data!$V$5:$V$5004,"Low") -> 75 | D6: =IFERROR(SUMPRODUCT(((Analysis_Data!$R$5:$R$5004="High")*(Analysis_Data!$Q$5:$Q$5004="0-7d")*(Analysis_Data!$V$5:$V$5004="Low"))*(Analysis_Data!$J$5:$J$5004=1))/C6,0) -> 0 | E6: =IFERROR(SUMPRODUCT(((Analysis_Data!$R$5:$R$5004="High")*(Analysis_Data!$Q$5:$Q$5004="0-7d")*(Analysis_Data!$V$5:$V$5004="Low"))*Analysis_Data!$E$5:$E$5004)/C6,0) -> 35.623867 | F6: =IFERROR(SUMPRODUCT(((Analysis_Data!$R$5:$R$5004="High")*(Analysis_Data!$Q$5:$Q$5004="0-7d")*(Analysis_Data!$V$5:$V$5004="Low"))*Analysis_Data!$F$5:$F$5004)/C6,0) -> 3.56 | G6: =IFERROR(SUMPRODUCT(((Analysis_Data!$R$5:$R$5004="High")*(Analysis_Data!$Q$5:$Q$5004="0-7d")*(Analysis_Data!$V$5:$V$5004="Low"))*Analysis_Data!$U$5:$U$5004)/C6,0) -> 1.892313e-06 | H6: =SUMPRODUCT(((Analysis_Data!$R$5:$R$5004="High")*(Analysis_Data!$Q$5:$Q$5004="0-7d")*(Analysis_Data!$V$5:$V$5004="Low"))*Analysis_Data!$W$5:$W$5004) -> 0.0017206037
A7: Engaged but At Risk | B7: High engagement + elevated model risk | C7: =COUNTIFS(Analysis_Data!$R$5:$R$5004,"High",Analysis_Data!$V$5:$V$5004,"High")+COUNTIFS(Analysis_Data!$R$5:$R$5004,"High",Analysis_Data!$V$5:$V$5004,"Critical") -> 0 | D7: =IFERROR(SUMPRODUCT(((Analysis_Data!$R$5:$R$5004="High")*((Analysis_Data!$V$5:$V$5004="High")+(Analysis_Data!$V$5:$V$5004="Critical")))*(Analysis_Data!$J$5:$J$5004=1))/C7,0) -> 0 | E7: =IFERROR(SUMPRODUCT(((Analysis_Data!$R$5:$R$5004="High")*((Analysis_Data!$V$5:$V$5004="High")+(Analysis_Data!$V$5:$V$5004="Critical")))*Analysis_Data!$E$5:$E$5004)/C7,0) -> 0 | F7: =IFERROR(SUMPRODUCT(((Analysis_Data!$R$5:$R$5004="High")*((Analysis_Data!$V$5:$V$5004="High")+(Analysis_Data!$V$5:$V$5004="Critical")))*Analysis_Data!$F$5:$F$5004)/C7,0) -> 0 | G7: =IFERROR(SUMPRODUCT(((Analysis_Data!$R$5:$R$5004="High")*((Analysis_Data!$V$5:$V$5004="High")+(Analysis_Data!$V$5:$V$5004="Critical")))*Analysis_Data!$U$5:$U$5004)/C7,0) -> 0 | H7: =SUMPRODUCT(((Analysis_Data!$R$5:$R$5004="High")*((Analysis_Data!$V$5:$V$5004="High")+(Analysis_Data!$V$5:$V$5004="Critical")))*Analysis_Data!$W$5:$W$5004) -> 0
